2020-07-31 08:45:10,188 ERROR: Exception on /favicon.ico [GET] [in /home/dana/Стільниця/FLASK_MICROBLOG/env/lib/python3.7/site-packages/flask/app.py:1892]
Traceback (most recent call last):
  File "/home/dana/Стільниця/FLASK_MICROBLOG/env/lib/python3.7/site-packages/flask/app.py", line 2447, in wsgi_app
    response = self.full_dispatch_request()
  File "/home/dana/Стільниця/FLASK_MICROBLOG/env/lib/python3.7/site-packages/flask/app.py", line 1952, in full_dispatch_request
    rv = self.handle_user_exception(e)
  File "/home/dana/Стільниця/FLASK_MICROBLOG/env/lib/python3.7/site-packages/flask/app.py", line 1821, in handle_user_exception
    reraise(exc_type, exc_value, tb)
  File "/home/dana/Стільниця/FLASK_MICROBLOG/env/lib/python3.7/site-packages/flask/_compat.py", line 39, in reraise
    raise value
  File "/home/dana/Стільниця/FLASK_MICROBLOG/env/lib/python3.7/site-packages/flask/app.py", line 1948, in full_dispatch_request
    rv = self.preprocess_request()
  File "/home/dana/Стільниця/FLASK_MICROBLOG/env/lib/python3.7/site-packages/flask/app.py", line 2242, in preprocess_request
    rv = func()
  File "/home/dana/Стільниця/FLASK_MICROBLOG/microblog/app/main/routes.py", line 18, in before_request
    if current_user.is_authenticated:
  File "/home/dana/Стільниця/FLASK_MICROBLOG/env/lib/python3.7/site-packages/werkzeug/local.py", line 347, in __getattr__
    return getattr(self._get_current_object(), name)
  File "/home/dana/Стільниця/FLASK_MICROBLOG/env/lib/python3.7/site-packages/werkzeug/local.py", line 306, in _get_current_object
    return self.__local()
  File "/home/dana/Стільниця/FLASK_MICROBLOG/env/lib/python3.7/site-packages/flask_login/utils.py", line 26, in <lambda>
    current_user = LocalProxy(lambda: _get_user())
  File "/home/dana/Стільниця/FLASK_MICROBLOG/env/lib/python3.7/site-packages/flask_login/utils.py", line 346, in _get_user
    current_app.login_manager._load_user()
  File "/home/dana/Стільниця/FLASK_MICROBLOG/env/lib/python3.7/site-packages/flask_login/login_manager.py", line 318, in _load_user
    user = self._user_callback(user_id)
  File "/home/dana/Стільниця/FLASK_MICROBLOG/microblog/app/models.py", line 142, in load_user
    return User.query.get(int(id))
  File "/home/dana/Стільниця/FLASK_MICROBLOG/env/lib/python3.7/site-packages/flask_sqlalchemy/__init__.py", line 512, in __get__
    mapper = orm.class_mapper(type)
  File "/home/dana/Стільниця/FLASK_MICROBLOG/env/lib/python3.7/site-packages/sqlalchemy/orm/base.py", line 451, in class_mapper
    mapper = _inspect_mapped_class(class_, configure=configure)
  File "/home/dana/Стільниця/FLASK_MICROBLOG/env/lib/python3.7/site-packages/sqlalchemy/orm/base.py", line 430, in _inspect_mapped_class
    mapper._configure_all()
  File "/home/dana/Стільниця/FLASK_MICROBLOG/env/lib/python3.7/site-packages/sqlalchemy/orm/mapper.py", line 1354, in _configure_all
    configure_mappers()
  File "/home/dana/Стільниця/FLASK_MICROBLOG/env/lib/python3.7/site-packages/sqlalchemy/orm/mapper.py", line 3276, in configure_mappers
    raise e
sqlalchemy.exc.InvalidRequestError: One or more mappers failed to initialize - can't proceed with initialization of other mappers. Triggering mapper: 'mapped class User->user'. Original exception was: Class <class 'app.models.Message'> does not have a mapped column named 'recipient_id'
2020-07-31 08:49:16,096 INFO: Microblog startup [in /home/dana/Стільниця/FLASK_MICROBLOG/microblog/app/__init__.py:83]
2020-07-31 08:49:20,236 ERROR: Exception on / [GET] [in /home/dana/Стільниця/FLASK_MICROBLOG/env/lib/python3.7/site-packages/flask/app.py:1892]
Traceback (most recent call last):
  File "/home/dana/Стільниця/FLASK_MICROBLOG/env/lib/python3.7/site-packages/flask/app.py", line 2447, in wsgi_app
    response = self.full_dispatch_request()
  File "/home/dana/Стільниця/FLASK_MICROBLOG/env/lib/python3.7/site-packages/flask/app.py", line 1952, in full_dispatch_request
    rv = self.handle_user_exception(e)
  File "/home/dana/Стільниця/FLASK_MICROBLOG/env/lib/python3.7/site-packages/flask/app.py", line 1821, in handle_user_exception
    reraise(exc_type, exc_value, tb)
  File "/home/dana/Стільниця/FLASK_MICROBLOG/env/lib/python3.7/site-packages/flask/_compat.py", line 39, in reraise
    raise value
  File "/home/dana/Стільниця/FLASK_MICROBLOG/env/lib/python3.7/site-packages/flask/app.py", line 1948, in full_dispatch_request
    rv = self.preprocess_request()
  File "/home/dana/Стільниця/FLASK_MICROBLOG/env/lib/python3.7/site-packages/flask/app.py", line 2242, in preprocess_request
    rv = func()
  File "/home/dana/Стільниця/FLASK_MICROBLOG/microblog/app/main/routes.py", line 18, in before_request
    if current_user.is_authenticated:
  File "/home/dana/Стільниця/FLASK_MICROBLOG/env/lib/python3.7/site-packages/werkzeug/local.py", line 347, in __getattr__
    return getattr(self._get_current_object(), name)
  File "/home/dana/Стільниця/FLASK_MICROBLOG/env/lib/python3.7/site-packages/werkzeug/local.py", line 306, in _get_current_object
    return self.__local()
  File "/home/dana/Стільниця/FLASK_MICROBLOG/env/lib/python3.7/site-packages/flask_login/utils.py", line 26, in <lambda>
    current_user = LocalProxy(lambda: _get_user())
  File "/home/dana/Стільниця/FLASK_MICROBLOG/env/lib/python3.7/site-packages/flask_login/utils.py", line 346, in _get_user
    current_app.login_manager._load_user()
  File "/home/dana/Стільниця/FLASK_MICROBLOG/env/lib/python3.7/site-packages/flask_login/login_manager.py", line 318, in _load_user
    user = self._user_callback(user_id)
  File "/home/dana/Стільниця/FLASK_MICROBLOG/microblog/app/models.py", line 142, in load_user
    return User.query.get(int(id))
  File "/home/dana/Стільниця/FLASK_MICROBLOG/env/lib/python3.7/site-packages/flask_sqlalchemy/__init__.py", line 512, in __get__
    mapper = orm.class_mapper(type)
  File "/home/dana/Стільниця/FLASK_MICROBLOG/env/lib/python3.7/site-packages/sqlalchemy/orm/base.py", line 451, in class_mapper
    mapper = _inspect_mapped_class(class_, configure=configure)
  File "/home/dana/Стільниця/FLASK_MICROBLOG/env/lib/python3.7/site-packages/sqlalchemy/orm/base.py", line 430, in _inspect_mapped_class
    mapper._configure_all()
  File "/home/dana/Стільниця/FLASK_MICROBLOG/env/lib/python3.7/site-packages/sqlalchemy/orm/mapper.py", line 1354, in _configure_all
    configure_mappers()
  File "/home/dana/Стільниця/FLASK_MICROBLOG/env/lib/python3.7/site-packages/sqlalchemy/orm/mapper.py", line 3280, in configure_mappers
    mapper._post_configure_properties()
  File "/home/dana/Стільниця/FLASK_MICROBLOG/env/lib/python3.7/site-packages/sqlalchemy/orm/mapper.py", line 1967, in _post_configure_properties
    prop.init()
  File "/home/dana/Стільниця/FLASK_MICROBLOG/env/lib/python3.7/site-packages/sqlalchemy/orm/interfaces.py", line 197, in init
    self.do_init()
  File "/home/dana/Стільниця/FLASK_MICROBLOG/env/lib/python3.7/site-packages/sqlalchemy/orm/relationships.py", line 2076, in do_init
    self._process_dependent_arguments()
  File "/home/dana/Стільниця/FLASK_MICROBLOG/env/lib/python3.7/site-packages/sqlalchemy/orm/relationships.py", line 2105, in _process_dependent_arguments
    setattr(self, attr, attr_value())
  File "/home/dana/Стільниця/FLASK_MICROBLOG/env/lib/python3.7/site-packages/sqlalchemy/ext/declarative/clsregistry.py", line 326, in __call__
    x = eval(self.arg, globals(), self._dict)
  File "<string>", line 1, in <module>
  File "/home/dana/Стільниця/FLASK_MICROBLOG/env/lib/python3.7/site-packages/sqlalchemy/ext/declarative/clsregistry.py", line 222, in __getattr__
    % (self.cls, key)
sqlalchemy.exc.InvalidRequestError: Class <class 'app.models.Message'> does not have a mapped column named 'recipient_id'
