2020-07-31 08:50:52,138 ERROR: Exception on /favicon.ico [GET] [in /home/dana/Стільниця/FLASK_MICROBLOG/env/lib/python3.7/site-packages/flask/app.py:1892]
Traceback (most recent call last):
  File "/home/dana/Стільниця/FLASK_MICROBLOG/env/lib/python3.7/site-packages/flask/app.py", line 2447, in wsgi_app
    response = self.full_dispatch_request()
  File "/home/dana/Стільниця/FLASK_MICROBLOG/env/lib/python3.7/site-packages/flask/app.py", line 1952, in full_dispatch_request
    rv = self.handle_user_exception(e)
  File "/home/dana/Стільниця/FLASK_MICROBLOG/env/lib/python3.7/site-packages/flask/app.py", line 1821, in handle_user_exception
    reraise(exc_type, exc_value, tb)
  File "/home/dana/Стільниця/FLASK_MICROBLOG/env/lib/python3.7/site-packages/flask/_compat.py", line 39, in reraise
    raise value
  File "/home/dana/Стільниця/FLASK_MICROBLOG/env/lib/python3.7/site-packages/flask/app.py", line 1948, in full_dispatch_request
    rv = self.preprocess_request()
  File "/home/dana/Стільниця/FLASK_MICROBLOG/env/lib/python3.7/site-packages/flask/app.py", line 2242, in preprocess_request
    rv = func()
  File "/home/dana/Стільниця/FLASK_MICROBLOG/microblog/app/main/routes.py", line 18, in before_request
    if current_user.is_authenticated:
  File "/home/dana/Стільниця/FLASK_MICROBLOG/env/lib/python3.7/site-packages/werkzeug/local.py", line 347, in __getattr__
    return getattr(self._get_current_object(), name)
  File "/home/dana/Стільниця/FLASK_MICROBLOG/env/lib/python3.7/site-packages/werkzeug/local.py", line 306, in _get_current_object
    return self.__local()
  File "/home/dana/Стільниця/FLASK_MICROBLOG/env/lib/python3.7/site-packages/flask_login/utils.py", line 26, in <lambda>
    current_user = LocalProxy(lambda: _get_user())
  File "/home/dana/Стільниця/FLASK_MICROBLOG/env/lib/python3.7/site-packages/flask_login/utils.py", line 346, in _get_user
    current_app.login_manager._load_user()
  File "/home/dana/Стільниця/FLASK_MICROBLOG/env/lib/python3.7/site-packages/flask_login/login_manager.py", line 318, in _load_user
    user = self._user_callback(user_id)
  File "/home/dana/Стільниця/FLASK_MICROBLOG/microblog/app/models.py", line 140, in load_user
    return User.query.get(int(id))
  File "/home/dana/Стільниця/FLASK_MICROBLOG/env/lib/python3.7/site-packages/flask_sqlalchemy/__init__.py", line 512, in __get__
    mapper = orm.class_mapper(type)
  File "/home/dana/Стільниця/FLASK_MICROBLOG/env/lib/python3.7/site-packages/sqlalchemy/orm/base.py", line 451, in class_mapper
    mapper = _inspect_mapped_class(class_, configure=configure)
  File "/home/dana/Стільниця/FLASK_MICROBLOG/env/lib/python3.7/site-packages/sqlalchemy/orm/base.py", line 430, in _inspect_mapped_class
    mapper._configure_all()
  File "/home/dana/Стільниця/FLASK_MICROBLOG/env/lib/python3.7/site-packages/sqlalchemy/orm/mapper.py", line 1354, in _configure_all
    configure_mappers()
  File "/home/dana/Стільниця/FLASK_MICROBLOG/env/lib/python3.7/site-packages/sqlalchemy/orm/mapper.py", line 3276, in configure_mappers
    raise e
sqlalchemy.exc.InvalidRequestError: One or more mappers failed to initialize - can't proceed with initialization of other mappers. Triggering mapper: 'mapped class User->user'. Original exception was: Class <class 'app.models.Message'> does not have a mapped column named 'recipient_id'
2020-07-31 08:51:35,848 INFO: Microblog startup [in /home/dana/Стільниця/FLASK_MICROBLOG/microblog/app/__init__.py:83]
2020-07-31 08:51:57,950 ERROR: Exception on /user/susan [GET] [in /home/dana/Стільниця/FLASK_MICROBLOG/env/lib/python3.7/site-packages/flask/app.py:1892]
Traceback (most recent call last):
  File "/home/dana/Стільниця/FLASK_MICROBLOG/env/lib/python3.7/site-packages/flask/app.py", line 2447, in wsgi_app
    response = self.full_dispatch_request()
  File "/home/dana/Стільниця/FLASK_MICROBLOG/env/lib/python3.7/site-packages/flask/app.py", line 1952, in full_dispatch_request
    rv = self.handle_user_exception(e)
  File "/home/dana/Стільниця/FLASK_MICROBLOG/env/lib/python3.7/site-packages/flask/app.py", line 1821, in handle_user_exception
    reraise(exc_type, exc_value, tb)
  File "/home/dana/Стільниця/FLASK_MICROBLOG/env/lib/python3.7/site-packages/flask/_compat.py", line 39, in reraise
    raise value
  File "/home/dana/Стільниця/FLASK_MICROBLOG/env/lib/python3.7/site-packages/flask/app.py", line 1950, in full_dispatch_request
    rv = self.dispatch_request()
  File "/home/dana/Стільниця/FLASK_MICROBLOG/env/lib/python3.7/site-packages/flask/app.py", line 1936, in dispatch_request
    return self.view_functions[rule.endpoint](**req.view_args)
  File "/home/dana/Стільниця/FLASK_MICROBLOG/env/lib/python3.7/site-packages/flask_login/utils.py", line 272, in decorated_view
    return func(*args, **kwargs)
  File "/home/dana/Стільниця/FLASK_MICROBLOG/microblog/app/main/routes.py", line 80, in user
    next_url=next_url, prev_url=prev_url, form=form)
  File "/home/dana/Стільниця/FLASK_MICROBLOG/env/lib/python3.7/site-packages/flask/templating.py", line 140, in render_template
    ctx.app,
  File "/home/dana/Стільниця/FLASK_MICROBLOG/env/lib/python3.7/site-packages/flask/templating.py", line 120, in _render
    rv = template.render(context)
  File "/home/dana/Стільниця/FLASK_MICROBLOG/env/lib/python3.7/site-packages/jinja2/environment.py", line 1090, in render
    self.environment.handle_exception()
  File "/home/dana/Стільниця/FLASK_MICROBLOG/env/lib/python3.7/site-packages/jinja2/environment.py", line 832, in handle_exception
    reraise(*rewrite_traceback_stack(source=source))
  File "/home/dana/Стільниця/FLASK_MICROBLOG/env/lib/python3.7/site-packages/jinja2/_compat.py", line 28, in reraise
    raise value.with_traceback(tb)
  File "/home/dana/Стільниця/FLASK_MICROBLOG/microblog/app/templates/user.html", line 1, in top-level template code
    {% extends "base.html" %}
  File "/home/dana/Стільниця/FLASK_MICROBLOG/microblog/app/templates/base.html", line 1, in top-level template code
    {% extends 'bootstrap/base.html' %}
  File "/home/dana/Стільниця/FLASK_MICROBLOG/env/lib/python3.7/site-packages/flask_bootstrap/templates/bootstrap/base.html", line 1, in top-level template code
    {% block doc -%}
  File "/home/dana/Стільниця/FLASK_MICROBLOG/env/lib/python3.7/site-packages/flask_bootstrap/templates/bootstrap/base.html", line 4, in block "doc"
    {%- block html %}
  File "/home/dana/Стільниця/FLASK_MICROBLOG/env/lib/python3.7/site-packages/flask_bootstrap/templates/bootstrap/base.html", line 20, in block "html"
    {% block body -%}
  File "/home/dana/Стільниця/FLASK_MICROBLOG/env/lib/python3.7/site-packages/flask_bootstrap/templates/bootstrap/base.html", line 23, in block "body"
    {% block content -%}
  File "/home/dana/Стільниця/FLASK_MICROBLOG/microblog/app/templates/base.html", line 57, in block "content"
    {% block app_content %}{% endblock %}
  File "/home/dana/Стільниця/FLASK_MICROBLOG/microblog/app/templates/user.html", line 25, in block "app_content"
    <form action="{{ url_for('unfollow', username=user.username) }}" method="post">
  File "/home/dana/Стільниця/FLASK_MICROBLOG/env/lib/python3.7/site-packages/flask/helpers.py", line 370, in url_for
    return appctx.app.handle_url_build_error(error, endpoint, values)
  File "/home/dana/Стільниця/FLASK_MICROBLOG/env/lib/python3.7/site-packages/flask/app.py", line 2216, in handle_url_build_error
    reraise(exc_type, exc_value, tb)
  File "/home/dana/Стільниця/FLASK_MICROBLOG/env/lib/python3.7/site-packages/flask/_compat.py", line 39, in reraise
    raise value
  File "/home/dana/Стільниця/FLASK_MICROBLOG/env/lib/python3.7/site-packages/flask/helpers.py", line 358, in url_for
    endpoint, values, method=method, force_external=external
  File "/home/dana/Стільниця/FLASK_MICROBLOG/env/lib/python3.7/site-packages/werkzeug/routing.py", line 2179, in build
    raise BuildError(endpoint, values, method, self)
werkzeug.routing.BuildError: Could not build url for endpoint 'unfollow' with values ['username']. Did you mean 'main.unfollow' instead?
